Date: Tue, 24 Jul 2018 12:38:19 -0700 (PDT)
From: Aaron Dickey <aaronmich...@gmail.com>
To: singularity <singu...@lbl.gov>
Message-Id: <1dd34fee-79d9-49c4-9360-06ee9ef27137@lbl.gov>
Subject: tar: This does not look like a tar archive tar: Exiting with
 failure status due to previous errors. Singularity 2-4 on vagrant on
 windows10
MIME-Version: 1.0
Content-Type: multipart/mixed; 
	boundary="----=_Part_16350_673263598.1532461099115"

------=_Part_16350_673263598.1532461099115
Content-Type: multipart/alternative; 
	boundary="----=_Part_16351_1462996302.1532461099116"

------=_Part_16351_1462996302.1532461099116
Content-Type: text/plain; charset=UTF-8
Content-Transfer-Encoding: 7bit

Hi,

Things had been going swimmingly until a few weeks ago. This set of 
image.create and build commands used to go off without a hitch. Now I am 
not able to use my favorite docker image as a singularity image base 
anymore:
cd .\singularity-2.4\
vagrant init singularityware/singularity-2.4
vagrant up
vagrant ssh
sudo singularity image.create --size 3000 drvm.img
sudo singularity build --writable drvm.img docker://990210oliver/drvm 
--debug

###Failure###
#Building into existing container: drvm.img
#Docker image path: index.docker.io/990210oliver/drvm:latest
#Cache folder set to /root/.singularity/docker
#[22/22] |===================================| 100.0%
#Importing: base Singularity environment
#Importing: 
/root/.singularity/docker/sha256:e190868d63f8f8b85b026e53b5724c3c2a4548e1d642953442559cfa5f79b2c9.tar.gz
#Importing: 
/root/.singularity/docker/sha256:909cd34c6fd77d398af1d93e9d4f7f76104903f237be3d4db7b345a19631f291.tar.gz
#Importing: 
/root/.singularity/docker/sha256:0b9bfabab7c119abe303f22a146ff78be4ab0abdc798b0a0e97e94e80238a7e8.tar.gz
#Importing: 
/root/.singularity/docker/sha256:a3ed95caeb02ffe68cdd9fd84406680ae93d633cb16422d00e8a7c22955b46d4.tar.gz
#Importing: 
/root/.singularity/docker/sha256:88ac4362f7a101fcdb62eb60e0b75b84b94cfe6a3b45d90266acf1c902cf8e36.tar.gz
#
#gzip: 
/root/.singularity/docker/sha256:88ac4362f7a101fcdb62eb60e0b75b84b94cfe6a3b45d90266acf1c902cf8e36.tar.gz: 
not in gzip format
#tar: This does not look like a tar archive
#tar: Exiting with failure status due to previous errors
#Cleaning up...
###Failure###

Also tried with singularity pull:
sudo singularity pull docker://990210oliver/drvm --size 3000 --name 
drvm.img --writable --debug
###Error###
WARNING: pull for Docker Hub is not guaranteed to produce the
WARNING: same image on repeated pull. Use Singularity Registry
WARNING: (shub://) to pull exactly equivalent images.
Traceback (most recent call last):
  File "/usr/local/libexec/singularity/python/import.py", line 109, in 
<module>
    main()
  File "/usr/local/libexec/singularity/python/import.py", line 86, in main
    layerfile=LAYERFILE)
  File "/usr/local/libexec/singularity/python/docker/main.py", line 83, in 
IMPORT
    client = DockerApiConnection(image=image, auth=auth)
  File "/usr/local/libexec/singularity/python/docker/api.py", line 89, in 
__init__
    self.load_image(kwargs['image'])
  File "/usr/local/libexec/singularity/python/docker/api.py", line 141, in 
load_image
    self.update_token()
  File "/usr/local/libexec/singularity/python/docker/api.py", line 152, in 
update_token
    response = self.get_tags(return_response=True)
  File "/usr/local/libexec/singularity/python/docker/api.py", line 271, in 
get_tags
    return_response=return_response)
  File "/usr/local/libexec/singularity/python/base.py", line 262, in get
    return_response=return_response)
  File "/usr/local/libexec/singularity/python/base.py", line 291, in 
submit_request
    response = urlopen(request)
  File "/usr/lib/python2.7/urllib2.py", line 154, in urlopen
    return opener.open(url, data, timeout)
  File "/usr/lib/python2.7/urllib2.py", line 429, in open
    response = self._open(req, data)
  File "/usr/lib/python2.7/urllib2.py", line 447, in _open
    '_open', req)
  File "/usr/lib/python2.7/urllib2.py", line 407, in _call_chain
    result = func(*args)
  File "/usr/lib/python2.7/urllib2.py", line 1241, in https_open
    context=self._context)
  File "/usr/lib/python2.7/urllib2.py", line 1201, in do_open
    r = h.getresponse(buffering=True)
  File "/usr/lib/python2.7/httplib.py", line 1136, in getresponse
    response.begin()
  File "/usr/lib/python2.7/httplib.py", line 453, in begin
    version, status, reason = self._read_status()
  File "/usr/lib/python2.7/httplib.py", line 409, in _read_status
    line = self.fp.readline(_MAXLINE + 1)
  File "/usr/lib/python2.7/socket.py", line 480, in readline
    data = self._sock.recv(self._rbufsize)
  File "/usr/lib/python2.7/ssl.py", line 756, in recv
    return self.read(buflen)
  File "/usr/lib/python2.7/ssl.py", line 643, in read
    v = self._sslobj.read(len)
socket.error: [Errno 104] Connection reset by peer
Cleaning up...
###Error###

Please help!

------=_Part_16351_1462996302.1532461099116
Content-Type: text/html; charset=utf-8
Content-Transfer-Encoding: quoted-printable

<div dir=3D"ltr">Hi,<div><br></div><div>Things had been going swimmingly un=
til a few weeks ago. This set of image.create and build commands used to go=
 off without a hitch. Now I am not able to use my favorite docker image as =
a singularity image base anymore:</div><div>cd .\singularity-2.4\<br></div>=
<div><div>vagrant init singularityware/singularity-2.4</div><div>vagrant up=
</div><div>vagrant ssh</div></div><div>sudo singularity image.create --size=
 3000 drvm.img<br></div><div>sudo singularity build --writable drvm.img doc=
ker://990210oliver/drvm --debug<br></div><div><br></div><div>###Failure###<=
/div><div><div>#Building into existing container: drvm.img</div><div>#Docke=
r image path: index.docker.io/990210oliver/drvm:latest</div><div>#Cache fol=
der set to /root/.singularity/docker</div><div>#[22/22] |=3D=3D=3D=3D=3D=3D=
=3D=3D=3D=3D=3D=3D=3D=3D=3D=3D=3D=3D=3D=3D=3D=3D=3D=3D=3D=3D=3D=3D=3D=3D=3D=
=3D=3D=3D=3D| 100.0%</div><div>#Importing: base Singularity environment</di=
v><div>#Importing: /root/.singularity/docker/sha256:e190868d63f8f8b85b026e5=
3b5724c3c2a4548e1d642953442559cfa5f79b2c9.tar.gz</div><div>#Importing: /roo=
t/.singularity/docker/sha256:909cd34c6fd77d398af1d93e9d4f7f76104903f237be3d=
4db7b345a19631f291.tar.gz</div><div>#Importing: /root/.singularity/docker/s=
ha256:0b9bfabab7c119abe303f22a146ff78be4ab0abdc798b0a0e97e94e80238a7e8.tar.=
gz</div><div>#Importing: /root/.singularity/docker/sha256:a3ed95caeb02ffe68=
cdd9fd84406680ae93d633cb16422d00e8a7c22955b46d4.tar.gz</div><div>#Importing=
: /root/.singularity/docker/sha256:88ac4362f7a101fcdb62eb60e0b75b84b94cfe6a=
3b45d90266acf1c902cf8e36.tar.gz</div><div>#</div><div>#gzip: /root/.singula=
rity/docker/sha256:88ac4362f7a101fcdb62eb60e0b75b84b94cfe6a3b45d90266acf1c9=
02cf8e36.tar.gz: not in gzip format</div><div>#tar: This does not look like=
 a tar archive</div><div>#tar: Exiting with failure status due to previous =
errors</div><div>#Cleaning up...</div></div><div>###Failure###<br></div><di=
v><br></div><div>Also tried with singularity pull:</div><div>sudo singulari=
ty pull docker://990210oliver/drvm --size 3000 --name drvm.img --writable -=
-debug<br></div><div>###Error###<br></div><div><div>WARNING: pull for Docke=
r Hub is not guaranteed to produce the</div><div>WARNING: same image on rep=
eated pull. Use Singularity Registry</div><div>WARNING: (shub://) to pull e=
xactly equivalent images.</div><div>Traceback (most recent call last):</div=
><div>=C2=A0 File &quot;/usr/local/libexec/singularity/python/import.py&quo=
t;, line 109, in &lt;module&gt;</div><div>=C2=A0 =C2=A0 main()</div><div>=
=C2=A0 File &quot;/usr/local/libexec/singularity/python/import.py&quot;, li=
ne 86, in main</div><div>=C2=A0 =C2=A0 layerfile=3DLAYERFILE)</div><div>=C2=
=A0 File &quot;/usr/local/libexec/singularity/python/docker/main.py&quot;, =
line 83, in IMPORT</div><div>=C2=A0 =C2=A0 client =3D DockerApiConnection(i=
mage=3Dimage, auth=3Dauth)</div><div>=C2=A0 File &quot;/usr/local/libexec/s=
ingularity/python/docker/api.py&quot;, line 89, in __init__</div><div>=C2=
=A0 =C2=A0 self.load_image(kwargs[&#39;image&#39;])</div><div>=C2=A0 File &=
quot;/usr/local/libexec/singularity/python/docker/api.py&quot;, line 141, i=
n load_image</div><div>=C2=A0 =C2=A0 self.update_token()</div><div>=C2=A0 F=
ile &quot;/usr/local/libexec/singularity/python/docker/api.py&quot;, line 1=
52, in update_token</div><div>=C2=A0 =C2=A0 response =3D self.get_tags(retu=
rn_response=3DTrue)</div><div>=C2=A0 File &quot;/usr/local/libexec/singular=
ity/python/docker/api.py&quot;, line 271, in get_tags</div><div>=C2=A0 =C2=
=A0 return_response=3Dreturn_response)</div><div>=C2=A0 File &quot;/usr/loc=
al/libexec/singularity/python/base.py&quot;, line 262, in get</div><div>=C2=
=A0 =C2=A0 return_response=3Dreturn_response)</div><div>=C2=A0 File &quot;/=
usr/local/libexec/singularity/python/base.py&quot;, line 291, in submit_req=
uest</div><div>=C2=A0 =C2=A0 response =3D urlopen(request)</div><div>=C2=A0=
 File &quot;/usr/lib/python2.7/urllib2.py&quot;, line 154, in urlopen</div>=
<div>=C2=A0 =C2=A0 return opener.open(url, data, timeout)</div><div>=C2=A0 =
File &quot;/usr/lib/python2.7/urllib2.py&quot;, line 429, in open</div><div=
>=C2=A0 =C2=A0 response =3D self._open(req, data)</div><div>=C2=A0 File &qu=
ot;/usr/lib/python2.7/urllib2.py&quot;, line 447, in _open</div><div>=C2=A0=
 =C2=A0 &#39;_open&#39;, req)</div><div>=C2=A0 File &quot;/usr/lib/python2.=
7/urllib2.py&quot;, line 407, in _call_chain</div><div>=C2=A0 =C2=A0 result=
 =3D func(*args)</div><div>=C2=A0 File &quot;/usr/lib/python2.7/urllib2.py&=
quot;, line 1241, in https_open</div><div>=C2=A0 =C2=A0 context=3Dself._con=
text)</div><div>=C2=A0 File &quot;/usr/lib/python2.7/urllib2.py&quot;, line=
 1201, in do_open</div><div>=C2=A0 =C2=A0 r =3D h.getresponse(buffering=3DT=
rue)</div><div>=C2=A0 File &quot;/usr/lib/python2.7/httplib.py&quot;, line =
1136, in getresponse</div><div>=C2=A0 =C2=A0 response.begin()</div><div>=C2=
=A0 File &quot;/usr/lib/python2.7/httplib.py&quot;, line 453, in begin</div=
><div>=C2=A0 =C2=A0 version, status, reason =3D self._read_status()</div><d=
iv>=C2=A0 File &quot;/usr/lib/python2.7/httplib.py&quot;, line 409, in _rea=
d_status</div><div>=C2=A0 =C2=A0 line =3D self.fp.readline(_MAXLINE + 1)</d=
iv><div>=C2=A0 File &quot;/usr/lib/python2.7/socket.py&quot;, line 480, in =
readline</div><div>=C2=A0 =C2=A0 data =3D self._sock.recv(self._rbufsize)</=
div><div>=C2=A0 File &quot;/usr/lib/python2.7/ssl.py&quot;, line 756, in re=
cv</div><div>=C2=A0 =C2=A0 return self.read(buflen)</div><div>=C2=A0 File &=
quot;/usr/lib/python2.7/ssl.py&quot;, line 643, in read</div><div>=C2=A0 =
=C2=A0 v =3D self._sslobj.read(len)</div><div>socket.error: [Errno 104] Con=
nection reset by peer</div><div>Cleaning up...</div></div><div>###Error###<=
br></div><div><br></div><div>Please help!</div></div>
------=_Part_16351_1462996302.1532461099116--

------=_Part_16350_673263598.1532461099115--
